<?xml version="1.0" encoding="utf-8"?>
<robot
  name="sr02h_v1">
  <link
    name="base_link">
    <inertial>
      <origin
        xyz="-0.00016099 4.8814E-06 0.086352"
        rpy="0 0 0" />
      <mass
        value="3.47645" />
      <inertia
        ixx="0.0055134"
        ixy="1.2232E-07"
        ixz="-2.9091E-06"
        iyy="0.0062779"
        iyz="1.3398E-06"
        izz="0.0056981" />
    </inertial>
    <visual>
      <origin
        xyz="0 0 0"
        rpy="0 0 0" />
      <geometry>
        <mesh
          filename="../meshes/base_link.STL" />
      </geometry>
      <material
        name="">
        <color
          rgba="0.89804 0.91765 0.92941 1" />
      </material>
    </visual>
  </link>

  <!-- Left leg -->
  <link
    name="left_hip_pitch_link">
    <inertial>
      <origin
        xyz="0.00279810917619723 0.0590226524396257 -0.023054852325909"
        rpy="0 0 0" />
      <mass
        value="0.7656491" />
      <inertia
        ixx="0.0022635"
        ixy="0.0000152"
        ixz="-0.0000264"
        iyy="0.0022500"
        iyz="0.0004700"
        izz="0.0022880" />
    </inertial>
    <visual>
      <origin
        xyz="0 0 0"
        rpy="0 0 0" />
      <geometry>
        <mesh
          filename="../meshes/left_hip_pitch.STL" />
      </geometry>
      <material
        name="">
        <color
          rgba="0.898039215686275 0.917647058823529 0.929411764705882 1" />
      </material>
    </visual>
  </link>
  <joint
    name="left_hip_pitch_joint"
    type="revolute">
    <origin
      xyz="0 0.058 0.064402"
      rpy="0 0 0" />
    <parent
      link="base_link" />
    <child
      link="left_hip_pitch_link" />
    <axis
      xyz="0 1 0" />
    <limit
      lower="-1.57"
      upper="1.57"
      effort="200"
      velocity="1000" />
  </joint>
  <link
    name="left_hip_roll_link">
    <inertial>
      <origin
        xyz="-0.0287467579295601 0.006862671680611 -0.050065719803612"
        rpy="0 0 0" />
      <mass
        value="2.1934957" />
      <inertia
        ixx="0.0087202"
        ixy="0.0000030"
        ixz="-0.0000195"
        iyy="0.0080842"
        iyz="0.0006387"
        izz="0.0031033" />
    </inertial>
    <visual>
      <origin
        xyz="0 0 0"
        rpy="0 0 0" />
      <geometry>
        <mesh
          filename="../meshes/left_hip_roll.STL" />
      </geometry>
      <material
        name="">
        <color
          rgba="0.898039215686275 0.917647058823529 0.929411764705882 1" />
      </material>
    </visual>
  </link>
  <joint
    name="left_hip_roll_joint"
    type="revolute">
    <origin
      xyz="0.02925 0.083 -0.045"
      rpy="0.0 0 0" />
    <parent
      link="left_hip_pitch_link" />
    <child
      link="left_hip_roll_link" />
    <axis
      xyz="1 0 0" />
    <limit
      lower="-0.5"
      upper="1.48"
      effort="200"
      velocity="1000" />
  </joint>
  <link
    name="left_hip_yaw_link">
    <inertial>
      <origin
        xyz="0.000859033670177278 0.00279230328050287 -0.12304698014429"
        rpy="0 0 0" />
      <mass
        value="0.9976927" />
      <inertia
        ixx="0.0085783"
        ixy="-0.0000067"
        ixz="-0.0002371"
        iyy="0.0082096"
        iyz="-0.0000642"
        izz="0.0023135" />
    </inertial>
    <visual>
      <origin
        xyz="0 0 0"
        rpy="0 0 0" />
      <geometry>
        <mesh
          filename="../meshes/left_hip_yaw.STL" />
      </geometry>
      <material
        name="">
        <color
          rgba="0.525490196078431 0.525490196078431 0.525490196078431 1" />
      </material>
    </visual>
  </link>
  <joint
    name="left_hip_yaw_joint"
    type="revolute">
    <origin
      xyz="-0.02925 0.012546 -0.132"
      rpy="0.0 0 0" />
    <parent
      link="left_hip_roll_link" />
    <child
      link="left_hip_yaw_link" />
    <axis
      xyz="0 0 1" />
    <limit
      lower="-2.56"
      upper="2.56"
      effort="200"
      velocity="1000" />
  </joint>
  <link
    name="left_knee_link">
    <inertial>
      <!-- xyz="0.00379968567191096 -0.0286803167036715 -0.0787126567331105" -->
      <origin
        xyz="0.00380647387196999 0.0005933403830604006 -0.0787130518689801"
        rpy="0 0 0" />
      <mass
        value="3.1894217" />
      <inertia
        ixx="0.0333329"
        ixy="-0.0000097"
        ixz="0.0001648"
        iyy="0.0344714"
        iyz="0.0000063"
        izz="0.0041155" />
    </inertial>
    <visual>
      <origin
        xyz="0 0 0"
        rpy="0 0 0" />
      <geometry>
        <mesh
          filename="../meshes/left_knee.STL" />
      </geometry>
      <material
        name="">
        <color
          rgba="0.898039215686275 0.917647058823529 0.929411764705882 1" />
      </material>
    </visual>
  </link>
  <joint
    name="left_knee_joint"
    type="revolute">
      <!-- xyz="-0.010001 0.02925 -0.2165" -->
    <origin
      xyz="-0.010001 0.0 -0.2165"
      rpy="0 0 0" />
    <parent
      link="left_hip_yaw_link" />
    <child
      link="left_knee_link" />
    <axis
      xyz="0 1 0" />
    <limit
      lower="-0.2"
      upper="2.55"
      effort="200"
      velocity="1000" />
  </joint>
  <link
    name="left_ankle_pitch_link">
    <inertial>
        <!-- xyz="0.00113044560504644 0.0202575770527545 -0.00399754920790896" -->
      <origin
        xyz="0.00113044560504644 0.0 -0.00399754920790896"
        rpy="0 0 0" />
      <mass
        value="0.0822317248177105" />
      <inertia
        ixx="0.0000188"
        ixy="0.0000000"
        ixz="0.0000012"
        iyy="0.0000105"
        iyz="-0.0000001"
        izz="0.0000149" />
    </inertial>
    <visual>
      <origin
        xyz="0 0 0"
        rpy="0 0 0" />
      <geometry>
        <mesh
          filename="../meshes/left_ankle_pitch.STL" />
      </geometry>
      <material
        name="">
        <color
          rgba="0.898039215686275 0.917647058823529 0.929411764705882 1" />
      </material>
    </visual>
  </link>
  <joint
    name="left_ankle_pitch_joint"
    type="revolute">
      <!-- xyz="0 -0.04925 -0.35" -->
    <origin
      xyz="0 0.0 -0.35"
      rpy="0 0 0" />
    <parent
      link="left_knee_link" />
    <child
      link="left_ankle_pitch_link" />
    <axis
      xyz="0 1 0" />
    <limit
      lower="-0.92"
      upper="0.61"
      effort="200"
      velocity="1000" />
  </joint>
  <link
    name="left_ankle_roll_link">
    <inertial>
      <!-- xyz="-0.0133847206447103 -2.45147304900328E-05 -0.0216901841484405" -->
      <origin
        xyz="0.006 -2.45147304900328E-05 -0.0216901841484405"
        rpy="1.5708 0 1.5708" />
      <mass
        value="0.528201582069976" />
      <inertia
        ixx="0.0014795"
        ixy="0.0000005"
        ixz="-0.0000005"
        iyy="0.0017176"
        iyz="0.0000473"
        izz="0.0003875" />
    </inertial>
    <visual>
      <origin
        xyz="0 0 0"
        rpy="0 0 0" />
      <geometry>
        <mesh
          filename="../meshes/left_ankle_roll.STL" />
      </geometry>
      <material
        name="">
        <color
          rgba="0.898039215686275 0.917647058823529 0.929411764705882 1" />
      </material>
    </visual>
    <collision>
      <origin
        xyz="0 0 0"
        rpy="0 0 0" />
      <geometry>
        <mesh
          filename="../meshes/left_ankle_roll.STL" />
      </geometry>
    </collision>
  </link>
  <joint
    name="left_ankle_roll_joint"
    type="revolute">
      <!-- xyz="0.018 0.02 -0.016" -->
     <origin
      xyz="0.0 0.0 -0.016"
      rpy="0 0 0" />
    <parent
      link="left_ankle_pitch_link" />
    <child
      link="left_ankle_roll_link" />
    <axis
      xyz="1 0 0" />
    <limit
      lower="-0.34"
      upper="0.34"
      effort="200"
      velocity="1000" />
  </joint>

  <!-- Right leg -->
  <link
    name="right_hip_pitch_link">
    <inertial>
      <origin
        xyz="0.00275303483830105 -0.0589431318461096 -0.0230018506588775"
        rpy="0 0 0" />
      <mass
        value="0.7656326" />
      <inertia
        ixx="0.0022636"
        ixy="-0.0000153"
        ixz="-0.0000266"
        iyy="0.0022496"
        iyz="-0.0004700"
        izz="0.0022883" />
    </inertial>
    <visual>
      <origin
        xyz="0 0 0"
        rpy="0 0 0" />
      <geometry>
        <mesh
          filename="../meshes/right_hip_pitch.STL" />
      </geometry>
      <material
        name="">
        <color
          rgba="0.898039215686275 0.917647058823529 0.929411764705882 1" />
      </material>
    </visual>
  </link>
  <joint
    name="right_hip_pitch_joint"
    type="revolute">
    <origin
      xyz="0 -0.058 0.064402"
      rpy="0 0 0" />
    <parent
      link="base_link" />
    <child
      link="right_hip_pitch_link" />
    <axis
      xyz="0 1 0" />
    <limit
      lower="-1.57"
      upper="1.57"
      effort="200"
      velocity="1000" />
  </joint>
  <link
    name="right_hip_roll_link">
    <inertial>
      <origin
        xyz="-0.0287405458180181 -0.00684507047904026 -0.0500718573507396"
        rpy="0 0 0" />
      <mass
        value="2.1934899" />
      <inertia
        ixx="0.0087195"
        ixy="-0.0000028"
        ixz="-0.0000196"
        iyy="0.0080840"
        iyz="-0.0006364"
        izz="0.0031028" />
    </inertial>
    <visual>
      <origin
        xyz="0 0 0"
        rpy="0 0 0" />
      <geometry>
        <mesh
          filename="../meshes/right_hip_roll.STL" />
      </geometry>
      <material
        name="">
        <color
          rgba="0.898039215686275 0.917647058823529 0.929411764705882 1" />
      </material>
    </visual>
  </link>
  <joint
    name="right_hip_roll_joint"
    type="revolute">
    <origin
      xyz="0.02925 -0.083 -0.045"
      rpy="0 0 0" />
    <parent
      link="right_hip_pitch_link" />
    <child
      link="right_hip_roll_link" />
    <axis
      xyz="1 0 0" />
    <limit
      lower="-1.48"
      upper="0.5"
      effort="200"
      velocity="1000" />
  </joint>
  <link
    name="right_hip_yaw_link">
    <inertial>
      <origin
        xyz="0.000860684373936552 -0.00280478971817624 -0.123053333692536"
        rpy="0 0 0" />
      <mass
        value="0.9784525" />
      <inertia
        ixx="0.0085242"
        ixy="0.0000068"
        ixz="-0.0002486"
        iyy="0.0081519"
        iyz="0.0000643"
        izz="0.0022687" />
    </inertial>
    <visual>
      <origin
        xyz="0 0 0"
        rpy="0 0 0" />
      <geometry>
        <mesh
          filename="../meshes/right_hip_yaw.STL" />
      </geometry>
      <material
        name="">
        <color
          rgba="0.525490196078431 0.525490196078431 0.525490196078431 1" />
      </material>
    </visual>
  </link>
  <joint
    name="right_hip_yaw_joint"
    type="revolute">
    <origin
      xyz="-0.02925 -0.012498 -0.132"
      rpy="0.0 0 0" />
    <parent
      link="right_hip_roll_link" />
    <child
      link="right_hip_yaw_link" />
    <axis
      xyz="0 0 1" />
    <limit
      lower="-2.56"
      upper="2.56"
      effort="200"
      velocity="1000" />
  </joint>
  <link
    name="right_knee_link">
    <inertial>
        <!-- xyz="0.00380647387196999 0.0286746596169396 -0.0787130518689801" -->
      <origin
        xyz="0.00380647387196999 -0.0005933403830604006 -0.0787130518689801"
        rpy="0 0 0" />
      <mass
        value="3.2233207" />
      <inertia
        ixx="0.0344376"
        ixy="-0.0000158"
        ixz="-0.0000106"
        iyy="0.0356006"
        iyz="0.0000409"
        izz="0.0041679" />
    </inertial>
    <visual>
      <origin
        xyz="0 0 0"
        rpy="0 0 0" />
      <geometry>
        <mesh
          filename="../meshes/right_knee.STL" />
      </geometry>
      <material
        name="">
        <color
          rgba="0.898039215686275 0.917647058823529 0.929411764705882 1" />
      </material>
    </visual>
  </link>
  <joint
    name="right_knee_joint"
    type="revolute">
    <!-- xyz="-0.010001 0.029268 -0.2165" -->
    <origin
      xyz="-0.010001 0.0 -0.2165"
      rpy="0 0 0" />
    <parent
      link="right_hip_yaw_link" />
    <child
      link="right_knee_link" />
    <axis
      xyz="0 1 0" />
    <limit
      lower="-0.2"
      upper="2.55"
      effort="200"
      velocity="1000" />
  </joint>
  <link
    name="right_ankle_pitch_link">
    <inertial>
        <!-- xyz="0.00111916308668597 -0.0200015765221475 -0.00395617997248809" -->
      <origin
        xyz="0.00111916308668597 0.0 -0.00395617997248809"
        rpy="0 0 0" />
      <mass
        value="0.0830607206768232" />
      <inertia
        ixx="0.0000193"
        ixy="0.0000000"
        ixz="0.0000013"
        iyy="0.0000105"
        iyz="0.0000000"
        izz="0.0000156" />
    </inertial>
    <visual>
      <origin
        xyz="0 0 0"
        rpy="0 0 0" />
      <geometry>
        <mesh
          filename="../meshes/right_ankle_pitch.STL" />
      </geometry>
      <material
        name="">
        <color
          rgba="0.898039215686275 0.917647058823529 0.929411764705882 1" />
      </material>
    </visual>
  </link>
  <joint
    name="right_ankle_pitch_joint"
    type="revolute">
    <!-- xyz="0 0.049224 -0.35" -->
    <origin
    xyz="0 0.0 -0.35"
      rpy="0 0 0" />
    <parent
      link="right_knee_link" />
    <child
      link="right_ankle_pitch_link" />
    <axis
      xyz="0 1 0" />
    <limit
      lower="-0.92"
      upper="0.61"
      effort="200"
      velocity="1000" />
  </joint>
  <link
    name="right_ankle_roll_link">
    <inertial>
        <!-- xyz="-0.0122252947190807 4.08734815837697E-06 -0.0228856102841919" -->
      <origin
        xyz="0.006 4.08734815837697E-06 -0.0228856102841919"
        rpy="0 0 0" />
      <mass
        value="0.511083104121839" />
      <inertia
        ixx="0.0003872"
        ixy="0.0000003"
        ixz="0.0000054"
        iyy="0.0014818"
        iyz="0.0000012"
        izz="0.0017207" />
    </inertial>
    <visual>
      <origin
        xyz="0 0 0"
        rpy="0 0 0" />
      <geometry>
        <mesh
          filename="../meshes/right_ankle_roll.STL" />
      </geometry>
      <material
        name="">
        <color
          rgba="0.647058823529412 0.619607843137255 0.588235294117647 1" />
      </material>
    </visual>
    <collision>
      <origin
        xyz="0 0 0"
        rpy="0 0 0" />
      <geometry>
        <mesh
          filename="../meshes/right_ankle_roll.STL" />
      </geometry>
    </collision>
  </link>
  <joint
    name="right_ankle_roll_joint"
    type="revolute">
    <!-- xyz="0.018 -0.020001 -0.015999" -->
    <origin
      xyz="0.0 0.0 -0.015999"
      rpy="0 0 0" />
    <parent
      link="right_ankle_pitch_link" />
    <child
      link="right_ankle_roll_link" />
    <axis
      xyz="1 0 0" />
    <limit
      lower="-0.34"
      upper="0.34"
      effort="200"
      velocity="1000" />
  </joint>

  <!-- Upper body -->
  <link
    name="waist_link">
    <inertial>
      <origin
        xyz="0.0050879 4.5814E-05 0.16257"
        rpy="0 0 0" />
      <mass
        value="14.05068" />
      <inertia
        ixx="0.16748"
        ixy="-0.0000291"
        ixz="0.00093"
        iyy="0.1398089"
        iyz="-0.0001101"
        izz="0.1088302" />
    </inertial>
    <visual>
      <origin
        xyz="0 0 0"
        rpy="0 0 0" />
      <geometry>
        <mesh
          filename="../meshes/upper_body.STL" />
      </geometry>
      <material
        name="">
        <color
          rgba="0.98824 0.98431 1 1" />
      </material>
    </visual>
    <collision>
      <origin xyz="0 0 0.2" rpy="0 0 0"/>
      <geometry>
        <box size="0.4 0.35 0.6"/>
      </geometry>
    </collision>
  </link>
  <joint
    name="waist_joint"
    type="fixed">
    <origin
      xyz="0 0 0.1699"
      rpy="0 0 0" />
    <parent
      link="base_link" />
    <child
      link="waist_link" />
    <axis
      xyz="0 0 1" />
    <limit
      lower="-2.13"
      upper="2.13"
      effort="200"
      velocity="1000" />
  </joint>

  <!-- Left arm -->
  <link
    name="left_shoulder_pitch_link">
    <inertial>
      <origin
        xyz="0.00344717610933352 0.0423351351893554 -0.00711074467629791"
        rpy="0 0 0" />
      <mass
        value="0.694216136614982" />
      <inertia
        ixx="0.0005761"
        ixy="0.0000185"
        ixz="-0.0000038"
        iyy="0.0006071"
        iyz="-0.0000024"
        izz="0.0005178" />
    </inertial>
    <visual>
      <origin
        xyz="0 0 0"
        rpy="0 0 0" />
      <geometry>
        <mesh
          filename="../meshes/left_shoulder_pitch.STL" />
      </geometry>
      <material
        name="">
        <color
          rgba="0.898039215686275 0.917647058823529 0.929411764705882 1" />
      </material>
    </visual>
  </link>
  <joint
    name="left_shoulder_pitch_joint"
    type="fixed">
    <origin
      xyz="0 0.1665 0.2571"
      rpy="0 -0.060291 0" />
    <parent
      link="waist_link" />
    <child
      link="left_shoulder_pitch_link" />
    <axis
      xyz="0 1 0" />
    <limit
      lower="-3.14"
      upper="0.79"
      effort="200"
      velocity="1000" />
  </joint>
  <link
    name="left_shoulder_roll_link">
    <inertial>
      <origin
        xyz="-0.043270597228175 0.00701098433964686 -0.0598413035588394"
        rpy="0 0 0" />
      <mass
        value="0.74618333831235" />
      <inertia
        ixx="0.0014406"
        ixy="0.0000034"
        ixz="-0.0000011"
        iyy="0.0007306"
        iyz="-0.0000010"
        izz="0.0012067" />
    </inertial>
    <visual>
      <origin
        xyz="0 0 0"
        rpy="0 0 0" />
      <geometry>
        <mesh
          filename="../meshes/left_shoulder_roll.STL" />
      </geometry>
      <material
        name="">
        <color
          rgba="0.647058823529412 0.619607843137255 0.588235294117647 1" />
      </material>
    </visual>
  </link>
  <joint
    name="left_shoulder_roll_joint"
    type="fixed">
    <origin
      xyz="0.04075 0.046 -0.008"
      rpy="0 0 0" />
    <parent
      link="left_shoulder_pitch_link" />
    <child
      link="left_shoulder_roll_link" />
    <axis
      xyz="1 0 0" />
    <limit
      lower="-0.19"
      upper="1.9"
      effort="200"
      velocity="1000" />
  </joint>
  <link
    name="left_shoulder_yaw_link">
    <inertial>
      <origin
        xyz="0.0112064544968605 -0.000982861798183604 -0.0977927475633144"
        rpy="0 0 0" />
      <mass
        value="0.703549133932797" />
      <inertia
        ixx="0.0015298"
        ixy="-0.0000144"
        ixz="0.0000037"
        iyy="0.0005460"
        iyz="0.0001661"
        izz="0.0015342" />
    </inertial>
    <visual>
      <origin
        xyz="0 0 0"
        rpy="0 0 0" />
      <geometry>
        <mesh
          filename="../meshes/left_shoulder_yaw.STL" />
      </geometry>
      <material
        name="">
        <color
          rgba="0.898039215686275 0.917647058823529 0.929411764705882 1" />
      </material>
    </visual>
  </link>
  <joint
    name="left_shoulder_yaw_joint"
    type="fixed">
    <origin
      xyz="-0.043 0.011038 -0.10895"
      rpy="0.087266 0 0" />
    <parent
      link="left_shoulder_roll_link" />
    <child
      link="left_shoulder_yaw_link" />
    <axis
      xyz="0 0 1" />
    <limit
      lower="-2.27"
      upper="2.27"
      effort="200"
      velocity="1000" />
  </joint>
  <link
    name="left_elbow_pitch_link">
    <inertial>
      <origin
        xyz="-0.00854577860337201 0.0363084945846682 -0.0544777497330614"
        rpy="0 0 0" />
      <mass
        value="0.637811279264698" />
      <inertia
        ixx="0.0008975"
        ixy="-0.0000311"
        ixz="0.0000028"
        iyy="0.0005157"
        iyz="0.0000751"
        izz="0.0010168" />
    </inertial>
    <visual>
      <origin
        xyz="0 0 0"
        rpy="0 0 0" />
      <geometry>
        <mesh
          filename="../meshes/left_elbow_pitch.STL" />
      </geometry>
      <material
        name="">
        <color
          rgba="0.647058823529412 0.619607843137255 0.588235294117647 1" />
      </material>
    </visual>
  </link>
  <joint
    name="left_elbow_pitch_joint"
    type="fixed">
    <origin
      xyz="0.015164 -0.034428 -0.119"
      rpy="0 0 0" />
    <parent
      link="left_shoulder_yaw_link" />
    <child
      link="left_elbow_pitch_link" />
    <axis
      xyz="0 1 0" />
    <limit
      lower="-2.32"
      upper="0.52"
      effort="200"
      velocity="1000" />
  </joint>
  <link
    name="left_elbow_yaw_link">
    <inertial>
      <origin
        xyz="0.00019382056947307 0.00135315993647023 -0.100678862080478"
        rpy="0 0 0" />
      <mass
        value="0.354680930251576" />
      <inertia
        ixx="0.0019202"
        ixy="0.0000198"
        ixz="0.0000026"
        iyy="0.0003323"
        iyz="0.0004175"
        izz="0.0017334" />
    </inertial>
    <visual>
      <origin
        xyz="0 0 0"
        rpy="0 0 0" />
      <geometry>
        <mesh
          filename="../meshes/left_elbow_yaw.STL" />
      </geometry>
      <material
        name="">
        <color
          rgba="1 1 1 1" />
      </material>
    </visual>
  </link>
  <joint
    name="left_elbow_yaw_joint"
    type="fixed">
    <origin
      xyz="-0.010169 0.035352 -0.1"
      rpy="0 0 0" />
    <parent
      link="left_elbow_pitch_link" />
    <child
      link="left_elbow_yaw_link" />
    <axis
      xyz="0 0 1" />
    <limit
      lower="-2.62"
      upper="2.62"
      effort="200"
      velocity="1000" />
  </joint>

  <!-- Right arm -->
  <link
    name="right_shoulder_pitch_link">
    <inertial>
      <origin
        xyz="0.00354003706576523 -0.0418890245059548 -0.010709975473008"
        rpy="0 0 0" />
      <mass
        value="0.681332877125899" />
      <inertia
        ixx="0.0005761"
        ixy="-0.0000185"
        ixz="-0.0000038"
        iyy="0.0006071"
        iyz="-0.0000024"
        izz="0.0005178" />
    </inertial>
    <visual>
      <origin
        xyz="0 0 0"
        rpy="0 0 0" />
      <geometry>
        <mesh
          filename="../meshes/right_shoulder_pitch.STL" />
      </geometry>
      <material
        name="">
        <color
          rgba="0.898039215686275 0.917647058823529 0.929411764705882 1" />
      </material>
    </visual>
  </link>
  <joint
    name="right_shoulder_pitch_joint"
    type="fixed">
    <origin
      xyz="0 -0.1665 0.2571"
      rpy="0 -0.060291 0" />
      <!-- rpy="-0.087266 -0.00043798 0" /> -->
    <parent
      link="waist_link" />
    <child
      link="right_shoulder_pitch_link" />
    <axis
      xyz="0 1 0" />
    <limit
      lower="-3.14"
      upper="0.79"
      effort="200"
      velocity="1000" />
  </joint>
  <link
    name="right_shoulder_roll_link">
    <inertial>
      <origin
        xyz="-0.0430809923613486 -0.00701173639454694 -0.0597938545328877"
        rpy="0 0 0" />
      <mass
        value="0.740046506400838" />
      <inertia
        ixx="0.0014406"
        ixy="0.0000034"
        ixz="-0.0000011"
        iyy="0.0007306"
        iyz="-0.0000010"
        izz="0.0012067" />
    </inertial>
    <visual>
      <origin
        xyz="0 0 0"
        rpy="0 0 0" />
      <geometry>
        <mesh
          filename="../meshes/right_shoulder_roll.STL" />
      </geometry>
      <material
        name="">
        <color
          rgba="0.647058823529412 0.619607843137255 0.588235294117647 1" />
      </material>
    </visual>
  </link>
  <joint
    name="right_shoulder_roll_joint"
    type="fixed">
    <!-- <origin -->
    <!--   xyz="0.04075 -0.045128 -0.011979" -->
    <!--   rpy="0.087266 0 0" /> -->
    <origin
      xyz="0.04075 -0.046 -0.008"
      rpy="0 0 0" />
    <parent
      link="right_shoulder_pitch_link" />
    <child
      link="right_shoulder_roll_link" />
    <axis
      xyz="1 0 0" />
    <limit
      lower="-1.9"
      upper="0.19"
      effort="200"
      velocity="1000" />
  </joint>
  <link
    name="right_shoulder_yaw_link">
    <inertial>
      <origin
        xyz="0.0112109895643617 -0.007498870931538 -0.0980614031050809"
        rpy="0 0 0" />
      <mass
        value="0.697149409567736" />
      <inertia
        ixx="0.0015298"
        ixy="0.0000144"
        ixz="0.0000037"
        iyy="0.0005460"
        iyz="-0.0001661"
        izz="0.0015342" />
    </inertial>
    <visual>
      <origin
        xyz="0 0 0"
        rpy="0 0 0" />
      <geometry>
        <mesh
          filename="../meshes/right_shoulder_yaw.STL" />
      </geometry>
      <material
        name="">
        <color
          rgba="0.898039215686275 0.917647058823529 0.929411764705882 1" />
      </material>
    </visual>
  </link>
  <joint
    name="right_shoulder_yaw_joint"
    type="fixed">
    <origin
      xyz="-0.043 -0.011038 -0.10895"
      rpy="-0.087266 0 0" />
    <parent
      link="right_shoulder_roll_link" />
    <child
      link="right_shoulder_yaw_link" />
    <axis
      xyz="0 0 1" />
    <limit
      lower="-2.27"
      upper="2.27"
      effort="200"
      velocity="1000" />
  </joint>
  <link
    name="right_elbow_pitch_link">
    <inertial>
      <origin
        xyz="-0.0083141132139176 -0.0409275161474876 -0.0509462242050707"
        rpy="0 0 0" />
      <mass
        value="0.630885670588017" />
      <inertia
        ixx="0.0008975"
        ixy="0.0000311"
        ixz="0.0000028"
        iyy="0.0005157"
        iyz="-0.0000751"
        izz="0.0010168" />
    </inertial>
    <visual>
      <origin
        xyz="0 0 0"
        rpy="0 0 0" />
      <geometry>
        <mesh
          filename="../meshes/right_elbow_pitch.STL" />
      </geometry>
      <material
        name="">
        <color
          rgba="0.647058823529412 0.619607843137255 0.588235294117647 1" />
      </material>
    </visual>
  </link>
  <joint
    name="right_elbow_pitch_joint"
    type="fixed">
    <origin
      xyz="0.015164 0.034428 -0.119"
      rpy="0 0 0" />
    <!-- <origin -->
    <!--   xyz="0.014909 0.024036 -0.12156" -->
    <!--   rpy="0 0 0" /> -->
    <parent
      link="right_shoulder_yaw_link" />
    <child
      link="right_elbow_pitch_link" />
    <axis
      xyz="0 1 0" />
    <limit
      lower="-2.32"
      upper="0.52"
      effort="200"
      velocity="1000" />
  </joint>
  <link
    name="right_elbow_yaw_link">
    <inertial>
      <origin
        xyz="0.000193053712131418 -0.0100877174352154 -0.102025317535736"
        rpy="0 0 0" />
      <mass
        value="0.345282077013092" />
      <inertia
        ixx="0.0019202"
        ixy="-0.0000198"
        ixz="0.0000026"
        iyy="0.0003323"
        iyz="-0.0004175"
        izz="0.0017334" />
    </inertial>
    <visual>
      <origin
        xyz="0 0 0"
        rpy="0 0 0" />
      <geometry>
        <mesh
          filename="../meshes/right_elbow_yaw.STL" />
      </geometry>
      <material
        name="">
        <color
          rgba="1 1 1 1" />
      </material>
    </visual>
  </link>
  <joint
    name="right_elbow_yaw_joint"
    type="fixed">
    <origin
      xyz="-0.010169 -0.035352 -0.1"
      rpy="0 0 0" />
    <!-- <origin -->
    <!--   xyz="-0.0099069 -0.044007 -0.096532" -->
    <!--   rpy="0 0 0" /> -->
    <parent
      link="right_elbow_pitch_link" />
    <child
      link="right_elbow_yaw_link" />
    <axis
      xyz="0 0 1" />
    <limit
      lower="-2.62"
      upper="2.62"
      effort="200"
      velocity="1000" />
  </joint>

  <!-- Head -->
  <link
    name="head_link">
    <inertial>
      <origin
        xyz="0.010687 -0.00052293 0.081441"
        rpy="0 0 0" />
      <mass
        value="0.9238" />
      <inertia
        ixx="0.00439"
        ixy="3E-05"
        ixz="-0.00032"
        iyy="0.00486"
        iyz="1E-05"
        izz="0.00393" />
    </inertial>
    <visual>
      <origin
        xyz="0 0 0"
        rpy="0 0 0" />
      <geometry>
        <mesh
          filename="../meshes/head.STL" />
      </geometry>
      <material
        name="">
        <color
          rgba="0.89804 0.91765 0.92941 1" />
      </material>
    </visual>
  </link>
  <joint
    name="head_joint"
    type="fixed">
    <origin
      xyz="0 0 0.3401"
      rpy="0 0 0" />
    <parent
      link="waist_link" />
    <child
      link="head_link" />
    <axis
      xyz="0 0 1" />
    <limit
      lower="-1.5"
      upper="1.5"
      effort="200"
      velocity="1000" />
  </joint>

</robot>
