<mujoco model="sr02h_v1">
  <compiler angle="radian"/>

  <asset>
    <mesh name="left_hip_pitch" file="meshes/left_hip_pitch.STL"/>
    <mesh name="left_hip_roll" file="meshes/left_hip_roll.STL"/>
    <mesh name="left_hip_yaw" file="meshes/left_hip_yaw.STL"/>
    <mesh name="left_knee" file="meshes/left_knee.STL"/>
    <mesh name="left_ankle_pitch" file="meshes/left_ankle_pitch.STL"/>
    <mesh name="left_ankle_roll" file="meshes/left_ankle_roll.STL"/>
    <mesh name="right_hip_pitch" file="meshes/right_hip_pitch.STL"/>
    <mesh name="right_hip_roll" file="meshes/right_hip_roll.STL"/>
    <mesh name="right_hip_yaw" file="meshes/right_hip_yaw.STL"/>
    <mesh name="right_knee" file="meshes/right_knee.STL"/>
    <mesh name="right_ankle_pitch" file="meshes/right_ankle_pitch.STL"/>
    <mesh name="right_ankle_roll" file="meshes/right_ankle_roll.STL"/>
    <mesh name="left_shoulder_pitch" file="meshes/left_shoulder_pitch.STL"/>
    <mesh name="left_shoulder_roll" file="meshes/left_shoulder_roll.STL"/>
    <mesh name="left_shoulder_yaw" file="meshes/left_shoulder_yaw.STL"/>
    <mesh name="left_elbow_pitch" file="meshes/left_elbow_pitch.STL"/>
    <mesh name="left_elbow_yaw" file="meshes/left_elbow_yaw.STL"/>
    <mesh name="right_shoulder_roll" file="meshes/right_shoulder_roll.STL"/>
    <mesh name="right_shoulder_yaw" file="meshes/right_shoulder_yaw.STL"/>
    <mesh name="right_elbow_pitch" file="meshes/right_elbow_pitch.STL"/>
    <mesh name="right_elbow_yaw" file="meshes/right_elbow_yaw.STL"/>
    <mesh name="head" file="meshes/head.STL"/>
  </asset>

  <worldbody>
    <body name="base_link" pos="0 0 0.75">
      <freejoint />
      <geom size="0.05 0.07" pos="0 0 0.08" type="cylinder" rgba="0.89804 0.91765 0.92941 1"/>
      <body name="left_hip_pitch_link" pos="0 0.058 0.064402">
        <inertial pos="0.00279811 0.0590227 -0.0230549" quat="0.635667 0.294909 -0.25916 0.664675" mass="0.765649" diaginertia="0.00273954 0.00226518 0.00179678"/>
        <joint name="left_hip_pitch_joint" pos="0 0 0" axis="0 1 0" range="-1.57 1.57" actuatorfrcrange="-130 130"/>
        <geom type="mesh" rgba="0.898039 0.917647 0.929412 1" mesh="left_hip_pitch"/>
        <body name="left_hip_roll_link" pos="0.02925 0.083 -0.045">
          <inertial pos="-0.0287468 0.00686267 -0.0500657" quat="0.998029 0.0627218 0.00169713 0.000589256" mass="2.1935" diaginertia="0.00872027 0.0081648 0.00302264"/>
          <joint name="left_hip_roll_joint" pos="0 0 0" axis="1 0 0" range="-0.5 1.48" actuatorfrcrange="-130 130"/>
          <geom type="mesh" rgba="0.898039 0.917647 0.929412 1" mesh="left_hip_roll"/>
          <body name="left_hip_yaw_link" pos="-0.02925 0.012546 -0.132">
            <inertial pos="0.000859034 0.0027923 -0.123047" quat="0.999791 -0.00555855 0.0188583 -0.00555928" mass="0.997693" diaginertia="0.00858731 0.00821025 0.00230384"/>
            <joint name="left_hip_yaw_joint" pos="0 0 0" axis="0 0 1" range="-2.56 2.56" actuatorfrcrange="-130 130"/>
            <geom type="mesh" rgba="0.52549 0.52549 0.52549 1" mesh="left_hip_yaw"/>
            <body name="left_knee_link" pos="-0.010001 0 -0.2165">
              <inertial pos="0.00380647 0.00059334 -0.0787131" quat="0.704094 -0.0019289 -0.00205998 0.710101" mass="3.18942" diaginertia="0.0344715 0.0333337 0.00411457"/>
              <joint name="left_knee_joint" pos="0 0 0" axis="0 1 0" range="-0.2 2.55" actuatorfrcrange="-130 130"/>
              <geom type="mesh" rgba="0.898039 0.917647 0.929412 1" mesh="left_knee"/>
              <body name="left_ankle_pitch_link" pos="0 0 -0.35">
                <inertial pos="0.00113045 0 -0.00399755" quat="0.691892 0.708783 -0.0971931 0.0972874" mass="0.0822317" diaginertia="1.91397e-05 1.45626e-05 1.04976e-05"/>
                <joint name="left_ankle_pitch_joint" pos="0 0 0" axis="0 1 0" range="-0.92 0.61" actuatorfrcrange="-75 75"/>
                <geom type="mesh" rgba="0.898039 0.917647 0.929412 1" mesh="left_ankle_pitch"/>
                <body name="left_ankle_roll_link" pos="0 0 -0.016">
                  <inertial pos="0.006 -2.45147e-05 -0.0216902" quat="0.707703 0.0127307 -0.012371 0.706287" mass="0.528202" diaginertia="0.00171928 0.0014795 0.00038582"/>
                  <joint name="left_ankle_roll_joint" pos="0 0 0" axis="1 0 0" range="-0.34 0.34" actuatorfrcrange="-75 75"/>
                  <geom type="mesh" rgba="0.898039 0.917647 0.929412 1" mesh="left_ankle_roll"/>
                </body>
              </body>
            </body>
          </body>
        </body>
      </body>
      <body name="right_hip_pitch_link" pos="0 -0.058 0.064402">
        <inertial pos="0.00275303 -0.0589431 -0.0230019" quat="0.295135 0.635489 -0.66474 0.259172" mass="0.765633" diaginertia="0.0027395 0.0022653 0.00179669"/>
        <joint name="right_hip_pitch_joint" pos="0 0 0" axis="0 1 0" range="-1.57 1.57" actuatorfrcrange="-130 130"/>
        <geom type="mesh" rgba="0.898039 0.917647 0.929412 1" mesh="right_hip_pitch"/>
        <body name="right_hip_roll_link" pos="0.02925 -0.083 -0.045">
          <inertial pos="-0.0287405 -0.00684507 -0.0500719" quat="0.998043 -0.0625016 0.00171536 -0.000407591" mass="2.19349" diaginertia="0.00871957 0.00816402 0.00302271"/>
          <joint name="right_hip_roll_joint" pos="0 0 0" axis="1 0 0" range="-1.48 0.5" actuatorfrcrange="-130 130"/>
          <geom type="mesh" rgba="0.898039 0.917647 0.929412 1" mesh="right_hip_roll"/>
          <body name="right_hip_yaw_link" pos="-0.02925 -0.012498 -0.132">
            <inertial pos="0.000860684 -0.00280479 -0.123053" quat="0.999773 0.00558237 0.0198002 0.00545366" mass="0.978452" diaginertia="0.00853411 0.00815256 0.00225813"/>
            <joint name="right_hip_yaw_joint" pos="0 0 0" axis="0 0 1" range="-2.56 2.56" actuatorfrcrange="-130 130"/>
            <geom type="mesh" rgba="0.52549 0.52549 0.52549 1" mesh="right_hip_yaw"/>
            <body name="right_knee_link" pos="-0.010001 0 -0.2165">
              <inertial pos="0.00380647 -0.00059334 -0.0787131" quat="0.702284 0.000581247 -0.000340368 0.711896" mass="3.22332" diaginertia="0.0356009 0.0344374 0.00416784"/>
              <joint name="right_knee_joint" pos="0 0 0" axis="0 1 0" range="-0.2 2.55" actuatorfrcrange="-130 130"/>
              <geom type="mesh" rgba="0.898039 0.917647 0.929412 1" mesh="right_knee"/>
              <body name="right_ankle_pitch_link" pos="0 0 -0.35">
                <inertial pos="0.00111916 0 -0.00395618" quat="0.698832 0.698832 -0.10786 0.10786" mass="0.0830607" diaginertia="1.97111e-05 1.51889e-05 1.05e-05"/>
                <joint name="right_ankle_pitch_joint" pos="0 0 0" axis="0 1 0" range="-0.92 0.61" actuatorfrcrange="-75 75"/>
                <geom type="mesh" rgba="0.898039 0.917647 0.929412 1" mesh="right_ankle_pitch"/>
                <body name="right_ankle_roll_link" pos="0 0 -0.015999">
                  <inertial pos="0.006 4.08735e-06 -0.0228856" quat="0.00186938 0.708535 0.00168593 0.705672" mass="0.511083" diaginertia="0.00172073 0.00148179 0.000387178"/>
                  <joint name="right_ankle_roll_joint" pos="0 0 0" axis="1 0 0" range="-0.34 0.34" actuatorfrcrange="-75 75"/>
                  <geom type="mesh" rgba="0.647059 0.619608 0.588235 1" mesh="right_ankle_roll"/>
                </body>
              </body>
            </body>
          </body>
        </body>
      </body>
      <body name="waist_link" pos="0 0 0.1699">
        <inertial pos="0.0050879 4.5814e-05 0.16257" quat="0.999967 -0.00176402 -0.00792572 -0.000570994" mass="14.0507" diaginertia="0.167495 0.139809 0.108815"/>
        <joint name="waist_joint" pos="0 0 0" axis="0 0 1" range="-2.13 2.13" actuatorfrcrange="-130 130"/>
        <geom size="0.1 0.12 0.165" pos="0 0 0.16" type="box" rgba="0.98824 0.98431 1 1"/>
        <body name="left_shoulder_pitch_link" pos="0 0.1665 0.2571" quat="0.999546 0 -0.0301409 0">
          <inertial pos="0.00344718 0.0423351 -0.00711074" quat="0.843856 0.0101112 0.0292772 0.535674" mass="0.694216" diaginertia="0.000615881 0.000567583 0.000517536"/>
          <joint name="left_shoulder_pitch_joint" pos="0 0 0" axis="0 1 0" range="-3.14 0.79" actuatorfrcrange="-75 75"/>
          <geom type="mesh" rgba="0.898039 0.917647 0.929412 1" mesh="left_shoulder_pitch"/>
          <body name="left_shoulder_roll_link" pos="0.04075 0.046 -0.008">
            <inertial pos="-0.0432706 0.00701098 -0.0598413" quat="0.706368 0.707837 0.00336513 2.20827e-05" mass="0.746183" diaginertia="0.00144062 0.0012067 0.000730582"/>
            <joint name="left_shoulder_roll_joint" pos="0 0 0" axis="1 0 0" range="-0.19 1.9" actuatorfrcrange="-75 75"/>
            <geom type="mesh" rgba="0.647059 0.619608 0.588235 1" mesh="left_shoulder_roll"/>
            <body name="left_shoulder_yaw_link" pos="-0.043 0.011038 -0.10895" quat="0.999048 0.0436192 0 0">
              <inertial pos="0.0112065 -0.000982862 -0.0977927" quat="0.553372 0.463546 -0.452111 0.523927" mass="0.703549" diaginertia="0.00156143 0.00152996 0.000518612"/>
              <joint name="left_shoulder_yaw_joint" pos="0 0 0" axis="0 0 1" range="-2.27 2.27" actuatorfrcrange="-75 75"/>
              <geom type="mesh" rgba="0.898039 0.917647 0.929412 1" mesh="left_shoulder_yaw"/>
              <body name="left_elbow_pitch_link" pos="0.015164 -0.034428 -0.119">
                <inertial pos="-0.00854578 0.0363085 -0.0544777" quat="0.549239 0.437672 -0.486054 0.520125" mass="0.637811" diaginertia="0.00102784 0.000899936 0.000502228"/>
                <joint name="left_elbow_pitch_joint" pos="0 0 0" axis="0 1 0" range="-2.32 0.52" actuatorfrcrange="-75 75"/>
                <geom type="mesh" rgba="0.647059 0.619608 0.588235 1" mesh="left_elbow_pitch"/>
                <body name="left_elbow_yaw_link" pos="-0.010169 0.035352 -0.1">
                  <inertial pos="0.000193821 0.00135316 -0.100679" quat="0.794135 0.605398 -0.027861 0.0454691" mass="0.354681" diaginertia="0.00192123 0.00184755 0.000217129"/>
                  <joint name="left_elbow_yaw_joint" pos="0 0 0" axis="0 0 1" range="-2.62 2.62" actuatorfrcrange="-75 75"/>
                  <geom type="mesh" rgba="1 1 1 1" mesh="left_elbow_yaw"/>
                </body>
              </body>
            </body>
          </body>
        </body>
        <body name="right_shoulder_pitch_link" pos="0 -0.1665 0.2571" quat="0.999546 0 -0.0301409 0">
          <inertial pos="0.00354004 -0.041889 -0.01071" quat="0.536947 0.0214037 0.0390001 0.842442" mass="0.681333" diaginertia="0.000615738 0.000567862 0.0005174"/>
          <joint name="right_shoulder_pitch_joint" pos="0 0 0" axis="0 1 0" range="-3.14 0.79" actuatorfrcrange="-75 75"/>
          <geom size="0.038 0.039" type="cylinder" rgba="0.898039 0.917647 0.929412 1"/>
          <body name="right_shoulder_roll_link" pos="0.04075 -0.046 -0.008">
            <inertial pos="-0.043081 -0.00701174 -0.0597939" quat="0.706368 0.707837 0.00336513 2.20827e-05" mass="0.740047" diaginertia="0.00144062 0.0012067 0.000730582"/>
            <joint name="right_shoulder_roll_joint" pos="0 0 0" axis="1 0 0" range="-1.9 0.19" actuatorfrcrange="-75 75"/>
            <geom type="mesh" rgba="0.647059 0.619608 0.588235 1" mesh="right_shoulder_roll"/>
            <body name="right_shoulder_yaw_link" pos="-0.043 -0.011038 -0.10895" quat="0.999048 -0.0436192 0 0">
              <inertial pos="0.011211 -0.00749887 -0.0980614" quat="0.463546 0.553372 -0.523927 0.452111" mass="0.697149" diaginertia="0.00156143 0.00152996 0.000518612"/>
              <joint name="right_shoulder_yaw_joint" pos="0 0 0" axis="0 0 1" range="-2.27 2.27" actuatorfrcrange="-75 75"/>
              <geom type="mesh" rgba="0.898039 0.917647 0.929412 1" mesh="right_shoulder_yaw"/>
              <body name="right_elbow_pitch_link" pos="0.015164 0.034428 -0.119">
                <inertial pos="-0.00831411 -0.0409275 -0.0509462" quat="0.437672 0.549239 -0.520125 0.486054" mass="0.630886" diaginertia="0.00102784 0.000899936 0.000502228"/>
                <joint name="right_elbow_pitch_joint" pos="0 0 0" axis="0 1 0" range="-2.32 0.52" actuatorfrcrange="-75 75"/>
                <geom type="mesh" rgba="0.647059 0.619608 0.588235 1" mesh="right_elbow_pitch"/>
                <body name="right_elbow_yaw_link" pos="-0.010169 -0.035352 -0.1">
                  <inertial pos="0.000193054 -0.0100877 -0.102025" quat="0.605398 0.794135 -0.0454691 0.027861" mass="0.345282" diaginertia="0.00192123 0.00184755 0.000217129"/>
                  <joint name="right_elbow_yaw_joint" pos="0 0 0" axis="0 0 1" range="-2.62 2.62" actuatorfrcrange="-75 75"/>
                  <geom type="mesh" rgba="1 1 1 1" mesh="right_elbow_yaw"/>
                </body>
              </body>
            </body>
          </body>
        </body>
        <body name="head_link" pos="0 0 0.3401">
          <inertial pos="0.010687 -0.00052293 0.081441" quat="0.713122 0.167422 0.165155 0.660417" mass="0.9238" diaginertia="0.00486206 0.00455249 0.00376545"/>
          <joint name="head_joint" pos="0 0 0" axis="0 0 1" range="-1.5 1.5" actuatorfrcrange="-36 36"/>
          <geom type="mesh" rgba="0.89804 0.91765 0.92941 1" mesh="head"/>
        </body>
      </body>
    </body>
  </worldbody>
  <actuator>

    <!-- ================== 下肢 ================== -->
    <motor name="left_hip_pitch_joint"   joint="left_hip_pitch_joint"   ctrlrange="-200 200"/>
    <motor name="left_hip_roll_joint"    joint="left_hip_roll_joint"    ctrlrange="-200 200"/>
    <motor name="left_hip_yaw_joint"     joint="left_hip_yaw_joint"     ctrlrange="-200 200"/>
    <motor name="left_knee_joint"        joint="left_knee_joint"        ctrlrange="-200 200"/>
    <motor name="left_ankle_pitch_joint" joint="left_ankle_pitch_joint" ctrlrange="-200 200"/>
    <motor name="left_ankle_roll_joint"  joint="left_ankle_roll_joint"  ctrlrange="-200 200"/>

    <motor name="right_hip_pitch_joint"   joint="right_hip_pitch_joint"   ctrlrange="-200 200"/>
    <motor name="right_hip_roll_joint"    joint="right_hip_roll_joint"    ctrlrange="-200 200"/>
    <motor name="right_hip_yaw_joint"     joint="right_hip_yaw_joint"     ctrlrange="-200 200"/>
    <motor name="right_knee_joint"        joint="right_knee_joint"        ctrlrange="-200 200"/>
    <motor name="right_ankle_pitch_joint" joint="right_ankle_pitch_joint" ctrlrange="-200 200"/>
    <motor name="right_ankle_roll_joint"  joint="right_ankle_roll_joint"  ctrlrange="-200 200"/>

    <!-- ================== 躯干 ================== -->
    <motor name="waist_joint" joint="waist_joint" ctrlrange="-200 200"/>

    <!-- ================== 左臂 ================== -->
    <motor name="left_shoulder_pitch_joint" joint="left_shoulder_pitch_joint" ctrlrange="-200 200"/>
    <motor name="left_shoulder_roll_joint"  joint="left_shoulder_roll_joint"  ctrlrange="-200 200"/>
    <motor name="left_shoulder_yaw_joint"   joint="left_shoulder_yaw_joint"   ctrlrange="-200 200"/>
    <motor name="left_elbow_pitch_joint"    joint="left_elbow_pitch_joint"    ctrlrange="-200 200"/>
    <motor name="left_elbow_yaw_joint"      joint="left_elbow_yaw_joint"      ctrlrange="-200 200"/>

    <!-- ================== 右臂 ================== -->
    <motor name="right_shoulder_pitch_joint" joint="right_shoulder_pitch_joint" ctrlrange="-200 200"/>
    <motor name="right_shoulder_roll_joint"  joint="right_shoulder_roll_joint"  ctrlrange="-200 200"/>
    <motor name="right_shoulder_yaw_joint"   joint="right_shoulder_yaw_joint"   ctrlrange="-200 200"/>
    <motor name="right_elbow_pitch_joint"    joint="right_elbow_pitch_joint"    ctrlrange="-200 200"/>
    <motor name="right_elbow_yaw_joint"      joint="right_elbow_yaw_joint"      ctrlrange="-200 200"/>

    <!-- ================== 头部 ================== -->
    <motor name="head_joint" joint="head_joint" ctrlrange="-200 200"/>

  </actuator>

</mujoco>
