<mujoco model="sr02h_v1">
  <compiler angle="radian" meshdir="../meshes/"/>
  <statistic meansize="0.201559" extent="2.948112" center="0.00499457 0 0.337764"/>

  <default>
    <joint limited="true" damping="0.01" armature="0.01" frictionloss="0.01" />
    <equality solref="0.001 2" />
    <default class="visual">
      <geom type="mesh" contype="0" conaffinity="0" group="2" density="0"/>
    </default>
    <default class="collision">
        <!-- Coarse collision shapes collide with the floor, but not with each other. -->
        <geom group="1" priority="1" contype="1" conaffinity="0" rgba="0.89804 0.91765 0.92941 0" friction="1. 1.0 1.0" density="0"/>
    </default>
    <!-- <geom  condim='4' contype="1" conaffinity="15" solref='0.001 2' friction='1.9 1.2 1.2'/> -->
    <geom  condim='4' contype="1" conaffinity="15" solref='0.001 2' friction='0.9 0.2 0.2'/>
  </default>

  <asset>
    <!-- Set ground -->
    <texture name="grid" type="2d" builtin="checker" width="512" height="512" rgb1=".1 .2 .3" rgb2=".2 .3 .4"/>
    <material name="grid" texture="grid" texrepeat="1 1" texuniform="true" reflectance=".2"/>
  </asset>

  <option timestep="0.001" integrator="RK4">
    <flag frictionloss="enable" />
  </option>

  <asset>
    <material name="metal" rgba=".9 .95 .95 1"/>
    <material name="black" rgba="0 0 0 1"/>
    <material name="white" rgba="1 1 1 1"/>
    <material name="gray" rgba="0.4 0.4 0.4 1"/>
    <material name="transparent" rgba="0.5 0.5 0.5 1"/>
    <mesh name="base_link" file="meshes/base_link.STL"/>
    <mesh name="left_hip_pitch" file="meshes/left_hip_pitch.STL"/>
    <mesh name="left_hip_roll" file="meshes/left_hip_roll.STL"/>
    <mesh name="left_hip_yaw" file="meshes/left_hip_yaw.STL"/>
    <mesh name="left_knee" file="meshes/left_knee.STL"/>
    <mesh name="left_ankle_pitch" file="meshes/left_ankle_pitch.STL"/>
    <mesh name="left_ankle_roll" file="meshes/left_ankle_roll.STL"/>
    <mesh name="right_hip_pitch" file="meshes/right_hip_pitch.STL"/>
    <mesh name="right_hip_roll" file="meshes/right_hip_roll.STL"/>
    <mesh name="right_hip_yaw" file="meshes/right_hip_yaw.STL"/>
    <mesh name="right_knee" file="meshes/right_knee.STL"/>
    <mesh name="right_ankle_pitch" file="meshes/right_ankle_pitch.STL"/>
    <mesh name="right_ankle_roll" file="meshes/right_ankle_roll.STL"/>
    <mesh name="upper_body" file="meshes/upper_body.STL"/>
    <mesh name="left_shoulder_pitch" file="meshes/left_shoulder_pitch.STL"/>
    <mesh name="left_shoulder_roll" file="meshes/left_shoulder_roll.STL"/>
    <mesh name="left_shoulder_yaw" file="meshes/left_shoulder_yaw.STL"/>
    <mesh name="left_elbow_pitch" file="meshes/left_elbow_pitch.STL"/>
    <mesh name="left_elbow_yaw" file="meshes/left_elbow_yaw.STL" scale="0.001 0.001 0.001"/>
    <mesh name="right_shoulder_pitch" file="meshes/right_shoulder_pitch.STL"/>
    <mesh name="right_shoulder_roll" file="meshes/right_shoulder_roll.STL"/>
    <mesh name="right_shoulder_yaw" file="meshes/right_shoulder_yaw.STL"/>
    <mesh name="right_elbow_pitch" file="meshes/right_elbow_pitch.STL"/>
    <mesh name="right_elbow_yaw" file="meshes/right_elbow_yaw.STL" scale="0.001 0.001 0.001"/>
    <mesh name="head" file="meshes/head.STL"/>
  </asset>

  <worldbody>
    <!-- <body name="base_link" pos="0.48 0 0.96"> -->
    <body name="base_link" pos="0.48 0 0.22" quat="0.70710678 0 -0.70710678 0">
    <!-- <body name="base_link" pos="0.48 0 0.22" quat="0.70710678 0 0.70710678 0"> -->
      <freejoint/>
      <inertial pos="-0.00016099 4.8814e-06 0.086352" quat="0.503386 0.496667 0.495428 0.504456" mass="3.47645" diaginertia="0.0062779 0.00569814 0.00551335"/>
      <geom type="mesh" class="visual" mesh="base_link"/>
      <!-- Match IsaacLab training more closely: the training URDF has no base_link collision. -->
      <geom name="base_collision" type="box" class="collision" pos="0 0 0.07" size="0.13 0.15 0.11" contype="0" conaffinity="0"/>
      <site name="imu_site" pos="0 0 0" size="0.02" rgba="1 0 0 1" type="sphere" />
      <site name='imu' size='0.01' pos='0.0 0 0.0'/>

      <body name="left_hip_pitch_link" pos="0 0.058 0.064402">
        <inertial pos="0.00279811 0.0590227 -0.0230549" quat="0.635667 0.294909 -0.25916 0.664675" mass="0.765649" diaginertia="0.00273954 0.00226518 0.00179678"/>
        <joint name="left_hip_pitch_joint" pos="0 0 0" axis="0 1 0" range="-1.57 1.57" actuatorfrcrange="-130 130"/>
        <geom type="mesh" class="visual" mesh="left_hip_pitch"/>
        <body name="left_hip_roll_link" pos="0.02925 0.083 -0.045">
          <inertial pos="-0.0287468 0.00686267 -0.0500657" quat="0.998029 0.0627218 0.00169713 0.000589256" mass="2.1935" diaginertia="0.00872027 0.0081648 0.00302264"/>
          <joint name="left_hip_roll_joint" pos="0 0 0" axis="1 0 0" range="-0.5 1.48" actuatorfrcrange="-130 130"/>
          <geom type="mesh" class="visual" mesh="left_hip_roll"/>
          <body name="left_hip_yaw_link" pos="-0.02925 0.012546 -0.132">
            <inertial pos="0.000859034 0.0027923 -0.123047" quat="0.999791 -0.00555855 0.0188583 -0.00555928" mass="0.997693" diaginertia="0.00858731 0.00821025 0.00230384"/>
            <joint name="left_hip_yaw_joint" pos="0 0 0" axis="0 0 1" range="-2.56 2.56" actuatorfrcrange="-130 130"/>
            <geom type="mesh" class="visual" mesh="left_hip_yaw"/>
            <!-- Match training URDF: left_hip_yaw_link has a cylinder collision at xyz="0 0 -0.1", radius=0.052, length=0.2. -->
            <geom name="left_thigh_collision" type="cylinder" class="collision" pos="0 0 -0.1" size="0.052 0.1"/>
            <body name="left_knee_link" pos="-0.010001 0 -0.2165">
              <inertial pos="0.00380647 0.00059334 -0.0787131" quat="0.704094 -0.0019289 -0.00205998 0.710101" mass="3.18942" diaginertia="0.0344715 0.0333337 0.00411457"/>
              <joint name="left_knee_joint" pos="0 0 0" axis="0 1 0" range="-0.2 2.55" actuatorfrcrange="-130 130"/>
              <geom type="mesh" class="visual" mesh="left_knee"/>
              <!-- Match training URDF: left_knee_link has a cylinder collision at xyz="0 0 -0.13", radius=0.052, length=0.26. -->
              <geom name="left_shank_collision" type="cylinder" class="collision" pos="0 0 -0.13" size="0.052 0.13"/>
              <body name="left_ankle_pitch_link" pos="0 0 -0.35">
                <inertial pos="0.00113045 0 -0.00399755" quat="0.500022 0.499956 -0.500017 0.500004" mass="0.2" diaginertia="4.3137e-05 2.9623e-05 2.6222e-05"/>
                <joint name="left_ankle_pitch_joint" pos="0 0 0" axis="0 1 0" range="-0.92 0.61" actuatorfrcrange="-100 100"/>
                <geom type="mesh" class="visual" mesh="left_ankle_pitch"/>
                <body name="left_ankle_roll_link" pos="0 0 -0.016">
                  <inertial pos="0.006 -2.45147e-05 -0.0216902" quat="0.707793 0.00726632 0.706347 -0.00707932" mass="0.528202" diaginertia="0.00271856 0.0024795 0.00038654"/>
                  <joint name="left_ankle_roll_joint" pos="0 0 0" axis="1 0 0" range="-0.8 0.8" actuatorfrcrange="-100 100"/>
                  <geom type="mesh" class="visual" mesh="left_ankle_roll"/>
                  <geom type="mesh" class="collision" mesh="left_ankle_roll"/>
                </body>
              </body>
            </body>
          </body>
        </body>
      </body>
      <body name="right_hip_pitch_link" pos="0 -0.058 0.064402">
        <inertial pos="0.00275303 -0.0589431 -0.0230019" quat="0.295135 0.635489 -0.66474 0.259172" mass="0.765633" diaginertia="0.0027395 0.0022653 0.00179669"/>
        <joint name="right_hip_pitch_joint" pos="0 0 0" axis="0 1 0" range="-1.57 1.57" actuatorfrcrange="-130 130"/>
        <geom type="mesh" class="visual" mesh="right_hip_pitch"/>
        <body name="right_hip_roll_link" pos="0.02925 -0.083 -0.045">
          <inertial pos="-0.0287405 -0.00684507 -0.0500719" quat="0.998043 -0.0625016 0.00171536 -0.000407591" mass="2.19349" diaginertia="0.00871957 0.00816402 0.00302271"/>
          <joint name="right_hip_roll_joint" pos="0 0 0" axis="1 0 0" range="-1.48 0.5" actuatorfrcrange="-130 130"/>
          <geom type="mesh" class="visual" mesh="right_hip_roll"/>
          <body name="right_hip_yaw_link" pos="-0.02925 -0.012498 -0.132">
            <inertial pos="0.000860684 -0.00280479 -0.123053" quat="0.999773 0.00558237 0.0198002 0.00545366" mass="0.978452" diaginertia="0.00853411 0.00815256 0.00225813"/>
            <joint name="right_hip_yaw_joint" pos="0 0 0" axis="0 0 1" range="-2.56 2.56" actuatorfrcrange="-130 130"/>
            <geom type="mesh" class="visual" mesh="right_hip_yaw"/>
            <!-- Match training URDF: right_hip_yaw_link has a cylinder collision at xyz="0 0 -0.1", radius=0.052, length=0.2. -->
            <geom name="right_thigh_collision" type="cylinder" class="collision" pos="0 0 -0.1" size="0.052 0.1"/>
            <body name="right_knee_link" pos="-0.010001 0 -0.2165">
              <inertial pos="0.00380647 -0.00059334 -0.0787131" quat="0.702284 0.000581247 -0.000340368 0.711896" mass="3.22332" diaginertia="0.0356009 0.0344374 0.00416784"/>
              <joint name="right_knee_joint" pos="0 0 0" axis="0 1 0" range="-0.2 2.55" actuatorfrcrange="-130 130"/>
              <geom type="mesh" class="visual" mesh="right_knee"/>
              <!-- Match training URDF: right_knee_link has a cylinder collision at xyz="0 0 -0.13", radius=0.052, length=0.26. -->
              <geom name="right_shank_collision" type="cylinder" class="collision" pos="0 0 -0.13" size="0.052 0.13"/>
              <body name="right_ankle_pitch_link" pos="0 0 -0.35">
                <inertial pos="0.00111916 0 -0.00395618" quat="0.500017 0.500004 -0.500022 0.499956" mass="0.2" diaginertia="4.3137e-05 2.9623e-05 2.6222e-05"/>
                <joint name="right_ankle_pitch_joint" pos="0 0 0" axis="0 1 0" range="-0.92 0.61" actuatorfrcrange="-100 100"/>
                <geom type="mesh" class="visual" mesh="right_ankle_pitch"/>
                <body name="right_ankle_roll_link" pos="0 0 -0.015999">
                  <inertial pos="0.006 -2.45147e-05 -0.0216902" quat="0.707793 0.00726632 0.706347 -0.00707932" mass="0.528202" diaginertia="0.00271856 0.0024795 0.00038654"/>
                  <joint name="right_ankle_roll_joint" pos="0 0 0" axis="1 0 0" range="-0.8 0.8" actuatorfrcrange="-100 100"/>
                  <geom type="mesh" class="visual" mesh="right_ankle_roll"/>
                  <geom type="mesh" class="collision" mesh="right_ankle_roll"/>
                </body>
              </body>
            </body>
          </body>
        </body>
      </body>
      <body name="waist_link" pos="0 0 0.1699">
        <inertial pos="0.0050879 4.5814e-05 0.16257" quat="0.999967 -0.00176402 -0.00792572 -0.000570994" mass="18.4507" diaginertia="0.167495 0.139809 0.108815"/>
        <joint name="waist_joint" pos="0 0 0" axis="0 0 1" range="-2.13 2.13" actuatorfrcrange="-130 130"/>
        <geom type="mesh" class="visual" mesh="upper_body"/>
        <!-- Match colleague's BeyondMimic MJCF collision. MuJoCo box size is half-extents. -->
        <geom size="0.2 0.175 0.3" pos="0 0 0.2" type="box" class="collision"/>
        <body name="left_shoulder_pitch_link" pos="0 0.1665 0.2571">
          <inertial pos="0.00344718 0.0423351 -0.00711074" quat="0.843856 0.0101112 0.0292772 0.535674" mass="0.694216" diaginertia="0.000615881 0.000567583 0.000517536"/>
          <joint name="left_shoulder_pitch_joint" pos="0 0 0" axis="0 1 0" range="-3.14 0.79" actuatorfrcrange="-100 100"/>
          <geom type="mesh" class="visual" mesh="left_shoulder_pitch"/>
          <!-- Match colleague's BeyondMimic MJCF: shoulder/arm contacts are not collision geoms. -->
          <geom name="left_shoulder_collision" type="sphere" class="collision" pos="0.025 0.03 -0.005" size="0.07" contype="0" conaffinity="0"/>
          <body name="left_shoulder_roll_link" pos="0.04075 0.046 -0.008">
            <inertial pos="-0.0432706 0.00701098 -0.0598413" quat="0.71124 8.00439e-05 0.000546331 0.702949" mass="0.746183" diaginertia="0.00112597 0.00112597 0.00112597"/>
            <joint name="left_shoulder_roll_joint" pos="0 0 0" axis="1 0 0" range="-0.19 1.9" actuatorfrcrange="-100 100"/>
            <geom type="mesh" class="visual" mesh="left_shoulder_roll"/>
            <body name="left_shoulder_yaw_link" pos="-0.043 0.011038 -0.10895" quat="0.999048 0.0436192 0 0">
              <inertial pos="0.0112065 -0.000982862 -0.0977927" quat="0.598219 0.0452388 -0.0651491 0.797397" mass="0.703549" diaginertia="0.00157655 0.00152585 0.000507596"/>
              <joint name="left_shoulder_yaw_joint" pos="0 0 0" axis="0 0 1" range="-2.27 2.27" actuatorfrcrange="-100 100"/>
              <geom type="mesh" class="visual" mesh="left_shoulder_yaw"/>
              <!-- Match training URDF: shoulder_yaw_link has a cylinder collision at xyz="0 0 0.05", radius=0.04, length=0.2. -->
              <geom name="left_upper_arm_collision" type="cylinder" class="collision" pos="0 0 0.05" size="0.04 0.1"/>
              <body name="left_elbow_pitch_link" pos="0.015164 -0.034428 -0.119">
                <inertial pos="-0.00854578 0.0363085 -0.0544777" quat="0.5 0.5 -0.5 0.5" mass="0.637811" diaginertia="0.0008168 0.0005975 0.0005157"/>
                <joint name="left_elbow_pitch_joint" pos="0 0 0" axis="0 1 0" range="-2.32 0.52" actuatorfrcrange="-100 100"/>
                <geom type="mesh" class="visual" mesh="left_elbow_pitch"/>
                <!-- Match training URDF: elbow_pitch_link has a cylinder collision at xyz="-0.017 0.038 -0.17", radius=0.04, length=0.3. -->
                <geom name="left_elbow_collision" type="cylinder" class="collision" pos="-0.017 0.038 -0.17" size="0.04 0.15"/>
                <body name="left_elbow_yaw_link" pos="-0.010169 0.035352 -0.1">
                  <inertial pos="0.000193821 0.00135316 -0.100679" quat="0.707107 0 0 0.707107" mass="0.354681" diaginertia="0.0011323 0.0011202 0.0003334"/>
                  <joint name="left_elbow_yaw_joint" pos="0 0 0" axis="0 0 1" range="-2.62 2.62" actuatorfrcrange="-100 100"/>
                  <geom type="mesh" class="visual" mesh="left_elbow_yaw" pos="-0.041019 0.040975 -0.157804" quat="0.70710678 0.70710678 0 0"/>
                  <!-- Match colleague's BeyondMimic MJCF: shoulder/arm contacts are not collision geoms. -->
                  <geom name="left_forearm_collision" type="capsule" class="collision" size="0.04" fromto="0 0 -0.025 0 0 -0.18" contype="0" conaffinity="0"/>
                </body>
              </body>
            </body>
          </body>
        </body>
        <body name="right_shoulder_pitch_link" pos="0 -0.1665 0.2571">
          <inertial pos="0.00354004 -0.041889 -0.01071" quat="0.536947 0.0214037 0.0390001 0.842442" mass="0.681333" diaginertia="0.000615738 0.000567862 0.0005174"/>
          <joint name="right_shoulder_pitch_joint" pos="0 0 0" axis="0 1 0" range="-3.14 0.79" actuatorfrcrange="-100 100"/>
          <geom type="mesh" class="visual" mesh="right_shoulder_pitch"/>
          <!-- Match colleague's BeyondMimic MJCF: shoulder/arm contacts are not collision geoms. -->
          <geom name="right_shoulder_collision" type="sphere" class="collision" pos="0.025 -0.03 -0.005" size="0.07" contype="0" conaffinity="0"/>
          <body name="right_shoulder_roll_link" pos="0.04075 -0.046 -0.008">
            <inertial pos="-0.043081 -0.00701174 -0.0597939" quat="0.71124 8.00439e-05 0.000546331 0.702949" mass="0.740047" diaginertia="0.00112597 0.00112597 0.00112597"/>
            <joint name="right_shoulder_roll_joint" pos="0 0 0" axis="1 0 0" range="-1.9 0.19" actuatorfrcrange="-100 100"/>
            <geom type="mesh" class="visual" mesh="right_shoulder_roll"/>
            <body name="right_shoulder_yaw_link" pos="-0.043 -0.011038 -0.10895" quat="0.999048 -0.0436192 0 0">
              <inertial pos="0.011211 -0.00749887 -0.0980614" quat="0.797397 -0.0651491 0.0452388 0.598219" mass="0.697149" diaginertia="0.00157655 0.00152585 0.000507596"/>
              <joint name="right_shoulder_yaw_joint" pos="0 0 0" axis="0 0 1" range="-2.27 2.27" actuatorfrcrange="-100 100"/>
              <geom type="mesh" class="visual" mesh="right_shoulder_yaw"/>
              <!-- Match training URDF: shoulder_yaw_link has a cylinder collision at xyz="0 0 0.05", radius=0.04, length=0.2. -->
              <geom name="right_upper_arm_collision" type="cylinder" class="collision" pos="0 0 0.05" size="0.04 0.1"/>
              <body name="right_elbow_pitch_link" pos="0.015164 0.034428 -0.119">
                <inertial pos="-0.00831411 -0.0409275 -0.0509462" quat="0.5 0.5 -0.5 0.5" mass="0.630886" diaginertia="0.0008168 0.0005975 0.0005157"/>
                <joint name="right_elbow_pitch_joint" pos="0 0 0" axis="0 1 0" range="-2.32 0.52" actuatorfrcrange="-100 100"/>
                <geom type="mesh" class="visual" mesh="right_elbow_pitch"/>
                <!-- Match training URDF: elbow_pitch_link has a cylinder collision at xyz="-0.017 -0.038 -0.17", radius=0.04, length=0.3. -->
                <geom name="right_elbow_collision" type="cylinder" class="collision" pos="-0.017 -0.038 -0.17" size="0.04 0.15"/>
                <body name="right_elbow_yaw_link" pos="-0.010169 -0.035352 -0.1">
                  <inertial pos="0.000193054 -0.0100877 -0.102025" quat="0.707107 0 0 0.707107" mass="0.345282" diaginertia="0.0011323 0.0011202 0.0003334"/>
                  <joint name="right_elbow_yaw_joint" pos="0 0 0" axis="0 0 1" range="-2.62 2.62" actuatorfrcrange="-100 100"/>
                  <geom type="mesh" class="visual" mesh="right_elbow_yaw" pos="-0.041019 0.040975 -0.157804" quat="0.70710678 0.70710678 0 0"/>
                  <!-- Match colleague's BeyondMimic MJCF: shoulder/arm contacts are not collision geoms. -->
                  <geom name="right_forearm_collision" type="capsule" class="collision" size="0.04" fromto="0 0 -0.025 0 0 -0.18" contype="0" conaffinity="0"/>
                </body>
              </body>
            </body>
          </body>
        </body>
        <body name="head_link" pos="0 0 0.3401">
          <inertial pos="0.010687 -0.00052293 0.081441" quat="0.713122 0.167422 0.165155 0.660417" mass="0.9238" diaginertia="0.00486206 0.00455249 0.00376545"/>
          <joint name="head_joint" pos="0 0 0" axis="0 0 1" range="-1.5 1.5" actuatorfrcrange="-100 100"/>
          <geom type="mesh" class="visual" mesh="head"/>
          <!-- Match colleague's BeyondMimic MJCF: no head collision. -->
          <geom name="head_collision" type="sphere" class="collision" pos="0.01 0 0.085" size="0.105" contype="0" conaffinity="0"/>
        </body>
      </body>
    </body>
  </worldbody>

  <actuator>
    <motor name="left_hip_pitch_joint"   joint="left_hip_pitch_joint"   gear="1" ctrllimited="true" ctrlrange="-130 130"/>
    <motor name="left_hip_roll_joint"  joint="left_hip_roll_joint"  gear="1" ctrllimited="true" ctrlrange="-130 130"/>
    <motor name="left_hip_yaw_joint"  joint="left_hip_yaw_joint"  gear="1" ctrllimited="true" ctrlrange="-130 130"/>
    <motor name="left_knee_joint"  joint="left_knee_joint"  gear="1" ctrllimited="true" ctrlrange="-130 130"/>
    <motor name="left_ankle_pitch_joint"   joint="left_ankle_pitch_joint"   gear="1" ctrllimited="true" ctrlrange="-100 100"/>
    <motor name="left_ankle_roll_joint"  joint="left_ankle_roll_joint"  gear="1" ctrllimited="true" ctrlrange="-100 100"/>

    <motor name="right_hip_pitch_joint"  joint="right_hip_pitch_joint"  gear="1" ctrllimited="true" ctrlrange="-130 130"/>
    <motor name="right_hip_roll_joint"  joint="right_hip_roll_joint"  gear="1" ctrllimited="true" ctrlrange="-130 130"/>
    <motor name="right_hip_yaw_joint"  joint="right_hip_yaw_joint"  gear="1" ctrllimited="true" ctrlrange="-130 130"/>
    <motor name="right_knee_joint"  joint="right_knee_joint"  gear="1" ctrllimited="true" ctrlrange="-130 130"/>
    <motor name="right_ankle_pitch_joint"   joint="right_ankle_pitch_joint"   gear="1" ctrllimited="true" ctrlrange="-100 100"/>
    <motor name="right_ankle_roll_joint"  joint="right_ankle_roll_joint"  gear="1" ctrllimited="true" ctrlrange="-100 100"/>

    <motor name="waist_joint"  joint="waist_joint"  gear="1" ctrllimited="true" ctrlrange="-130 130"/>

    <motor name="left_shoulder_pitch_joint"  joint="left_shoulder_pitch_joint"  gear="1" ctrllimited="true" ctrlrange="-100 100"/>
    <motor name="left_shoulder_roll_joint"  joint="left_shoulder_roll_joint"  gear="1" ctrllimited="true" ctrlrange="-100 100"/>
    <motor name="left_shoulder_yaw_joint"  joint="left_shoulder_yaw_joint"  gear="1" ctrllimited="true" ctrlrange="-100 100"/>
    <motor name="left_elbow_pitch_joint"  joint="left_elbow_pitch_joint"  gear="1" ctrllimited="true" ctrlrange="-100 100"/>
    <motor name="left_elbow_yaw_joint"  joint="left_elbow_yaw_joint"  gear="1" ctrllimited="true" ctrlrange="-100 100"/>

    <motor name="right_shoulder_pitch_joint"  joint="right_shoulder_pitch_joint"  gear="1" ctrllimited="true" ctrlrange="-100 100"/>
    <motor name="right_shoulder_roll_joint"  joint="right_shoulder_roll_joint"  gear="1" ctrllimited="true" ctrlrange="-100 100"/>
    <motor name="right_shoulder_yaw_joint"  joint="right_shoulder_yaw_joint"  gear="1" ctrllimited="true" ctrlrange="-100 100"/>
    <motor name="right_elbow_pitch_joint"  joint="right_elbow_pitch_joint"  gear="1" ctrllimited="true" ctrlrange="-100 100"/>
    <motor name="right_elbow_yaw_joint"  joint="right_elbow_yaw_joint"  gear="1" ctrllimited="true" ctrlrange="-100 100"/>

    <motor name="head_joint"  joint="head_joint"  gear="1" ctrllimited="true" ctrlrange="-100 100"/>

  </actuator>

  <sensor>
    <accelerometer name="imu_acc" site="imu_site" />
    <gyro name="imu_gyro" site="imu_site" />
    <framepos name="imu_pos" objtype="site" objname="imu_site" />
    <framelinvel name="imu_linvel" objtype="site" objname="imu_site" />

    <framequat     name='orientation' objtype='site' noise='0.001' objname='imu'/>
    <framepos     name='position' objtype='site' noise='0.001' objname='imu'/>
    <gyro          name='angular-velocity'    site='imu' noise='0.005' cutoff='34.9'/>
    <velocimeter   name='linear-velocity'     site='imu' noise='0.001' cutoff='30'/>
    <accelerometer name='linear-acceleration' site='imu' noise='0.005' cutoff='157'/>
    <magnetometer  name='magnetometer'        site='imu'/>
  </sensor>

  <keyframe>
    <!--
      The simulator automatically applies the key named "reload_pose" after
      loading this model. This pose is frame 0 of getup clip 11, clipped to
      the same 0.9 soft joint limits used by training. x/y are moved to the
      scene center, z is adjusted to the MuJoCo collision floor, and velocities
      are zeroed for a stationary startup.

      To restore the standing startup for walking/running, swap the names of
      "reload_pose" and "standing_start" below.
    -->
    <!-- <key name="reload_pose"
         qpos="0 0 0.42279962 0.73052114 -0.18084651 -0.3138092 -0.57892764
               -1.413 -0.401 -0.06647861 -0.05505724 -0.40953624 0
               -0.30570105 0.07883377 -0.30596796 -0.0625 0.4622765 -0.19677986
               1.435563 0.5935 -0.0855 0.86577547 0.09582038 -0.31773615
               -0.49282685 -0.8307569 -0.12734081 -0.26947445 -0.72171474 0.21047631"
         qvel="0 0 0 0 0 0
               0 0 0 0 0 0 0 0 0 0 0 0
               0 0 0 0 0 0 0 0 0 0 0 0"/> -->

    <key name="standing_start"
         qpos="0.48 0 0.96 1 0 0 0
               0 0 0 0 0 0 0 0 0 0 0 0
               0 0 0 0 0 0 0 0 0 0 0 0"
         qvel="0 0 0 0 0 0
               0 0 0 0 0 0 0 0 0 0 0 0
               0 0 0 0 0 0 0 0 0 0 0 0"/>
  </keyframe>

</mujoco>
